<?xml version="1.0" ?>
<!-- =================================================================================== -->
<!-- |    This document was autogenerated by xacro from owl_68_robot.xacro             | -->
<!-- |    EDITING THIS FILE BY HAND IS NOT RECOMMENDED                                 | -->
<!-- =================================================================================== -->
<robot name="owl_robot">
  
  
  
  
  
  
  
  <link name="world"/>
  <joint name="virtual_joint" type="fixed">
    <origin rpy="0 0 3.14" xyz="0 -0.6 0.07"/>
    <parent link="world"/>
    <child link="base_link"/>
  </joint>
  <link name="base_link">
    <inertial>
      <origin rpy="0 0 0" xyz="0.06 -0.04 67.38"/>
      <mass value="3.588"/>
      <inertia ixx="0.03" ixy="0" ixz="0" iyy="0.03" iyz="0" izz="0.01"/>
    </inertial>
    <visual>
      <origin rpy="0 0 0" xyz="0 0 0"/>
      <geometry>
        <mesh filename="/Users/keval/Documents/VSCode/owl-spacemouse-controller/owl_68_robot_description/meshes/6.8/base_link.STL"/>
      </geometry>
      <material name="">
        <color rgba="0.79216 0.81961 0.93333 1"/>
      </material>
    </visual>
    <collision>
      <origin rpy="0 0 0" xyz="0 0 0"/>
      <geometry>
        <mesh filename="/Users/keval/Documents/VSCode/owl-spacemouse-controller/owl_68_robot_description/meshes/6.8/base_link.STL"/>
      </geometry>
    </collision>
  </link>
  <link name="Link_1">
    <inertial>
      <origin rpy="0 0 0" xyz="0 -0.06 0.01"/>
      <mass value="3.38"/>
      <inertia ixx="0.02" ixy="0" ixz="0" iyy="0.01" iyz="0" izz="0.02"/>
    </inertial>
    <visual>
      <origin rpy="0 0 0" xyz="0 0 0"/>
      <geometry>
        <mesh filename="/Users/keval/Documents/VSCode/owl-spacemouse-controller/owl_68_robot_description/meshes/6.8/Link_1.STL"/>
      </geometry>
      <material name="">
        <color rgba="0.792156862745098 0.819607843137255 0.933333333333333 1"/>
      </material>
    </visual>
    <collision>
      <origin rpy="0 0 0" xyz="0 0 0"/>
      <geometry>
        <mesh filename="/Users/keval/Documents/VSCode/owl-spacemouse-controller/owl_68_robot_description/meshes/6.8/Link_1.STL"/>
      </geometry>
    </collision>
  </link>
  <joint name="BJ" type="revolute">
    <origin rpy="0 0 0" xyz="0 0 0.1464"/>
    <parent link="base_link"/>
    <child link="Link_1"/>
    <axis xyz="0 0 1"/>
    <limit effort="500" lower="-3.14" upper="3.14" velocity="50"/>
  </joint>
  <link name="Link_2">
    <inertial>
      <origin rpy="0 0 0" xyz="-0.2 0 -0.03"/>
      <mass value="1.67"/>
      <inertia ixx="0.01" ixy="0" ixz="0.01" iyy="0.12" iyz="0" izz="0.12"/>
    </inertial>
    <visual>
      <origin rpy="0 0 0" xyz="0 0 0"/>
      <geometry>
        <mesh filename="/Users/keval/Documents/VSCode/owl-spacemouse-controller/owl_68_robot_description/meshes/6.8/Link_2.STL"/>
      </geometry>
      <material name="">
        <color rgba="0.792156862745098 0.819607843137255 0.933333333333333 1"/>
      </material>
    </visual>
    <collision>
      <origin rpy="0 0 0" xyz="0 0 0"/>
      <geometry>
        <mesh filename="/Users/keval/Documents/VSCode/owl-spacemouse-controller/owl_68_robot_description/meshes/6.8/Link_2.STL"/>
      </geometry>
    </collision>
  </link>
  <joint name="SJ" type="revolute">
    <origin rpy="-1.5708 0 0" xyz="0 0.0685 0.07"/>
    <parent link="Link_1"/>
    <child link="Link_2"/>
    <axis xyz="0 0 1"/>
    <limit effort="500" lower="-1.6" upper="1.6" velocity="50"/>
  </joint>
  <link name="Link_3">
    <inertial>
      <origin rpy="0 0 0" xyz="0.04 0 -0.06"/>
      <mass value="4.31"/>
      <inertia ixx="0.02" ixy="0" ixz="0" iyy="0.02" iyz="0" izz="0.02"/>
    </inertial>
    <visual>
      <origin rpy="0 0 0" xyz="0 0 0"/>
      <geometry>
        <mesh filename="/Users/keval/Documents/VSCode/owl-spacemouse-controller/owl_68_robot_description/meshes/6.8/Link_3.STL"/>
      </geometry>
      <material name="">
        <color rgba="0.792156862745098 0.819607843137255 0.933333333333333 1"/>
      </material>
    </visual>
    <collision>
      <origin rpy="0 0 0" xyz="0 0 0"/>
      <geometry>
        <mesh filename="/Users/keval/Documents/VSCode/owl-spacemouse-controller/owl_68_robot_description/meshes/6.8/Link_3.STL"/>
      </geometry>
    </collision>
  </link>
  <joint name="EJ" type="revolute">
    <origin rpy="-3.1416 0 0" xyz="0 -0.444 0.0132"/>
    <parent link="Link_2"/>
    <child link="Link_3"/>
    <axis xyz="0 0 1"/>
    <limit effort="500" lower="-2.8" upper="3.14" velocity="50"/>
  </joint>
  <link name="Link_4">
    <inertial>
      <origin rpy="0 0 0" xyz="-0.05 0 -0.2"/>
      <mass value="0.54456"/>
      <inertia ixx="0.005" ixy="0" ixz="0" iyy="0.005" iyz="0" izz="0.005"/>
    </inertial>
    <visual>
      <origin rpy="0 0 0" xyz="0 0 0"/>
      <geometry>
        <mesh filename="/Users/keval/Documents/VSCode/owl-spacemouse-controller/owl_68_robot_description/meshes/6.8/Link_4.STL"/>
      </geometry>
      <material name="">
        <color rgba="0.792156862745098 0.819607843137255 0.933333333333333 1"/>
      </material>
    </visual>
    <collision>
      <origin rpy="0 0 0" xyz="0 0 0"/>
      <geometry>
        <mesh filename="/Users/keval/Documents/VSCode/owl-spacemouse-controller/owl_68_robot_description/meshes/6.8/Link_4.STL"/>
      </geometry>
    </collision>
  </link>
  <joint name="W1J" type="revolute">
    <origin rpy="-1.5708 0 0" xyz="0.1175 0.036 0.0832"/>
    <parent link="Link_3"/>
    <child link="Link_4"/>
    <axis xyz="0 0 1"/>
    <limit effort="500" lower="-2.84489" upper="2.84489" velocity="50"/>
  </joint>
  <link name="Link_5">
    <inertial>
      <origin rpy="0 0 0" xyz="0.01 0.05 -0.05"/>
      <mass value="0.71069"/>
      <inertia ixx="0.005" ixy="0" ixz="0" iyy="0.005" iyz="0" izz="0.005"/>
    </inertial>
    <visual>
      <origin rpy="0 0 0" xyz="0 0 0"/>
      <geometry>
        <mesh filename="/Users/keval/Documents/VSCode/owl-spacemouse-controller/owl_68_robot_description/meshes/6.8/Link_5.STL"/>
      </geometry>
      <material name="">
        <color rgba="0.79216 0.81961 0.93333 1"/>
      </material>
    </visual>
    <collision>
      <origin rpy="0 0 0" xyz="0 0 0"/>
      <geometry>
        <mesh filename="/Users/keval/Documents/VSCode/owl-spacemouse-controller/owl_68_robot_description/meshes/6.8/Link_5.STL"/>
      </geometry>
    </collision>
  </link>
  <joint name="W2J" type="revolute">
    <origin rpy="-1.5708 0 0" xyz="0 -0.069635 0.3775"/>
    <parent link="Link_4"/>
    <child link="Link_5"/>
    <axis xyz="0 0 1"/>
    <limit effort="500" lower="-2.57" upper="2.78" velocity="50"/>
    
  </joint>
  <link name="Link_6">
    <inertial>
      <origin rpy="0 0 0" xyz="0 0.02 0"/>
      <mass value="0.203"/>
      <inertia ixx="0.005" ixy="0" ixz="0" iyy="0.005" iyz="0" izz="0.005"/>
    </inertial>
    <visual>
      <origin rpy="0 0 0" xyz="0 0 0"/>
      <geometry>
        <mesh filename="/Users/keval/Documents/VSCode/owl-spacemouse-controller/owl_68_robot_description/meshes/6.8/Link_6.STL"/>
      </geometry>
      <material name="">
        <color rgba="0.1098 0.1098 0.1098 1"/>
      </material>
    </visual>
    <collision>
      <origin rpy="0 0 0" xyz="0 0 0"/>
      <geometry>
        <mesh filename="/Users/keval/Documents/VSCode/owl-spacemouse-controller/owl_68_robot_description/meshes/6.8/Link_6.STL"/>
      </geometry>
    </collision>
  </link>
  <joint name="W3J" type="revolute">
    <origin rpy="1.5708 0 0" xyz="0.0985 -0.0545 0.05"/>
    <parent link="Link_5"/>
    <child link="Link_6"/>
    <axis xyz="0 0 1"/>
    <limit effort="500" lower="-3.1" upper="3.1" velocity="50"/>
  </joint>
  <link name="tool_mount">
    <inertial>
      <origin rpy="0 0 0" xyz="0 0 0"/>
      <mass value="1e-9"/>
      <inertia ixx="0" ixy="0" ixz="0" iyy="0" iyz="0" izz="0"/>
    </inertial>
  </link>
  <joint name="eef_to_tool_mount" type="fixed">
    <origin rpy="0 0 0" xyz="0 0 0.05"/>
    <parent link="Link_6"/>
    <child link="tool_mount"/>
    <axis xyz="0 0 0"/>
  </joint>
  <link name="tcp">
    <inertial>
      <origin rpy="0 0 0" xyz="0 0 0"/>
      <mass value="0"/>
      <inertia ixx="0" ixy="0" ixz="0" iyy="0" iyz="0" izz="0"/>
    </inertial>
  </link>
  <joint name="tcp_frame" type="fixed">
    <origin rpy="0 0 0" xyz="0 0 0"/>
    <parent link="tool_mount"/>
    <child link="tcp"/>
    <axis xyz="0 0 0"/>
  </joint>
</robot>
